Workbook

Sheet 表1｜綜計表
A1: 國立臺灣大學學生會總預算案
A2: 綜計表
A3: 第37屆第二期間（113-2）
A4: 2025年03月04日至2025年07月31日 | I4: 單位：新台幣元
A5: 單位別 | F5: 本期間期入 | G5: 佔本期間期入 | H5: 本期間期出 | I5: 佔本期間期出
A6: 款 | B6: 項 | C6: 說明 | F6: 預算數 | G6: 百分比 | H6: 預算數 | I6: 百分比
C7: 合計 | F7: ='表2｜主要表'!G7 -> 1898833 | G7: =F7/F7 -> 1 | H7: =H9+H21+H24 -> 1396063.7 | I7: =H7/H7 -> 1
A9: 1 | B9: 0 | C9: 行政部門 | F9: ='表2｜主要表'!G9 -> 1898833 | G9: ='表2｜主要表'!H9 -> 1 | H9: ='表2｜主要表'!I9 -> 1183895.1 | I9: ='表2｜主要表'!J9 -> 0.84802371
B10: 1 | C10: 會長 | F10: ='表2｜主要表'!G11 -> 1848833 | G10: ='表2｜主要表'!H11 -> 0.97366804 | H10: ='表2｜主要表'!I11 -> 150568.42 | I10: ='表2｜主要表'!J11 -> 0.12718054
B11: 2 | C11: 秘書處 | F11: 0 | G11: ='表2｜主要表'!H21 -> 0 | H11: ='表2｜主要表'!I21 -> 52684.211 | I11: ='表2｜主要表'!J21 -> 0.044500742
B12: 3 | C12: 財務部 | F12: ='表2｜主要表'!G26 -> 0 | G12: ='表2｜主要表'!H26 -> 0 | H12: ='表2｜主要表'!I26 -> 22905 | I12: ='表2｜主要表'!J26 -> 0.019347153
B13: 4 | C13: 學權部 | F13: 0 | G13: ='表2｜主要表'!H31 -> 0 | H13: ='表2｜主要表'!I31 -> 33789.474 | I13: ='表2｜主要表'!J31 -> 0.028540935
B14: 5 | C14: 學術部 | F14: 0 | G14: ='表2｜主要表'!H36 -> 0 | H14: ='表2｜主要表'!I36 -> 217811 | I14: ='表2｜主要表'!J36 -> 0.18397829
B15: 6 | C15: 文化部 | F15: ='表2｜主要表'!G71 -> 0 | G15: ='表2｜主要表'!H71 -> 0 | H15: ='表2｜主要表'!I71 -> 158663 | I15: ='表2｜主要表'!J71 -> 0.13401779
B16: 7 | C16: 公關部 | F16: ='表2｜主要表'!G76 -> 0 | G16: ='表2｜主要表'!H76 -> 0 | H16: ='表2｜主要表'!I76 -> 25684 | I16: ='表2｜主要表'!J76 -> 0.02169449
B17: 8 | C17: 選舉罷免執行委員會 | F17: ='表2｜主要表'!G81 -> 50000 | G17: ='表2｜主要表'!H81 -> 0.026331963 | H17: ='表2｜主要表'!I81 -> 376232 | I17: ='表2｜主要表'!J81 -> 0.31779167
B18: 9 | C18: 國際事務部 | F18: ='表2｜主要表'!G87 -> 0 | G18: ='表2｜主要表'!H87 -> 0 | H18: ='表2｜主要表'!I87 -> 104705 | I18: ='表2｜主要表'!J87 -> 0.088441112
B19: A | C19: 資訊部 | F19: ='表2｜主要表'!G101 -> 0 | G19: ='表2｜主要表'!H101 -> 0 | H19: ='表2｜主要表'!I101 -> 40853 | I19: ='表2｜主要表'!J101 -> 0.03450728
A21: 2 | B21: 0 | C21: 立法部門 | F21: ='表2｜主要表'!G112 -> 0 | G21: ='表2｜主要表'!H112 -> 0 | H21: ='表2｜主要表'!I112 -> 118337 | I21: ='表2｜主要表'!J112 -> 0.084764758
B22: 1 | C22: 學生代表大會 | F22: ='表2｜主要表'!G113 -> 0 | G22: ='表2｜主要表'!H113 -> 0 | H22: ='表2｜主要表'!I113 -> 118337 | I22: ='表2｜主要表'!J113 -> 1
A24: 3 | B24: 0 | C24: 司法部門 | F24: ='表2｜主要表'!G119 -> 0 | G24: ='表2｜主要表'!H119 -> 0 | H24: ='表2｜主要表'!I119 -> 93831.579 | I24: ='表2｜主要表'!J119 -> 0.067211532
B25: 1 | C25: 學生法院 | F25: ='表2｜主要表'!G120 -> 0 | G25: ='表2｜主要表'!H120 -> 0 | H25: ='表2｜主要表'!I120 -> 93831.579 | I25: ='表2｜主要表'!J120 -> 1
A27: 款 | C27: 部門預算
A28: 項 | C28: 單位預算
A29: 目 | C29: 附屬單位預算
A30: 節 | C30: 計畫名稱

Sheet 表2｜主要表
A1: 國立臺灣大學學生會總預算案
A2: 主要表
A3: 第37屆第二期間（113-2）
A4: 2025年03月04日至2025年07月31日
A5: 單位計畫別 | E5: 預算科目 | G5: 本期期入 | I5: 本期期出 | K5: 各計畫會費支出情形
A6: 款 | B6: 項 | C6: 目 | D6: 節 | E6: 代碼 | F6: 名稱 | G6: 預算數 | I6: 預算數
F7: 合計 | G7: =G9+G112+G119 -> 1898833 | H7: =G7/G7 -> 1 | I7: ='表3-2｜期出預算附屬表'!G6 -> 1396063.7 | J7: =I7/I7 -> 1
A9: 1 | B9: 0 | C9: 0 | D9: 0 | F9: 行政部門 | G9: ='表3-1｜期入預算附屬表'!G9 -> 1898833 | H9: =G9/G7 -> 1 | I9: ='表3-2｜期出預算附屬表'!G8 -> 1183895.1 | J9: ='表3-2｜期出預算附屬表'!H8 -> 0.84802371
B11: 1 | C11: 0 | D11: 0 | F11: 會長 | G11: ='表3-1｜期入預算附屬表'!G11 -> 1848833 | H11: =G11/G9 -> 0.97366804 | I11: ='表3-2｜期出預算附屬表'!G10 -> 150568.42 | J11: ='表3-2｜期出預算附屬表'!H10 -> 0.12718054
C13: 0 | D13: 1 | F13: 一般行政計畫 | G13: ='表3-1｜期入預算附屬表'!G13 -> 1848833 | H13: =G13/G7 -> 0.97366804 | I13: ='表3-2｜期出預算附屬表'!G11 -> 80410 | J13: ='表3-2｜期出預算附屬表'!H11 -> 0.53404293
C14: 0 | D14: 2 | F14: 2024 春季招募計畫 | G14: ='表3-1｜期入預算附屬表'!G19 -> 0 | H14: 0 | I14: ='表3-2｜期出預算附屬表'!G17 -> 3300 | J14: ='表3-2｜期出預算附屬表'!H17 -> 0.021916946 | K14: ="會費支出："&(I14-G14) -> 會費支出：3300
C15: 0 | D15: 3 | F15: 2025社團博覽會 | G15: ='表3-1｜期入預算附屬表'!G20 -> 0 | H15: 0 | I15: ='表3-2｜期出預算附屬表'!G20 -> 7880 | J15: ='表3-2｜期出預算附屬表'!H20 -> 0.052335011 | K15: ="會費支出："&(I15-G15) -> 會費支出：7880
C16: 0 | D16: 4 | F16: 學生會全會交流計畫 | G16: ='表3-1｜期入預算附屬表'!G21 -> 0 | H16: 0 | I16: ='表3-2｜期出預算附屬表'!G24 -> 14100 | J16: ='表3-2｜期出預算附屬表'!H24 -> 0.093645134 | K16: ="會費支出："&(I16-G16) -> 會費支出：14100
C17: 0 | D17: 5 | F17: 全校師生座談會計畫 | G17: 0 | H17: 0 | I17: ='表3-2｜期出預算附屬表'!G29 -> 19050 | J17: ='表3-2｜期出預算附屬表'!H29 -> 0.12652055 | K17: ="會費支出："&(I17-G17) -> 會費支出：19050
C18: 0 | D18: 6 | F18: 職棒會長來台大－職棒如何走向榮景及新球季展望 | G18: ='表3-1｜期入預算附屬表'!G23 -> 0 | H18: 0 | I18: ='表3-2｜期出預算附屬表'!G33 -> 18300 | J18: ='表3-2｜期出預算附屬表'!H33 -> 0.12153943 | K18: ="會費支出："&(I18-G18) -> 會費支出：18300
C19: 9 | D19: 9 | F19: 預備金 | G19: ='表3-1｜期入預算附屬表'!G21 -> 0 | H19: 0 | I19: ='表3-2｜期出預算附屬表'!G39 -> 7528.4211 | J19: ='表3-2｜期出預算附屬表'!H39 -> 0.05 | K19: 會費支出：7528
B21: 2 | C21: 0 | D21: 0 | F21: 秘書處 | G21: 0 | H21: 0 | I21: ='表3-2｜期出預算附屬表'!G42 -> 52684.211 | J21: ='表3-2｜期出預算附屬表'!H42 -> 0.044500742
C23: 0 | D23: 1 | F23: 一般行政計畫 | G23: ='表3-1｜期入預算附屬表'!G25 -> 0 | H23: 0 | I23: ='表3-2｜期出預算附屬表'!G43 -> 50050 | J23: ='表3-2｜期出預算附屬表'!H43 -> 0.95
C24: 9 | D24: 9 | F24: 預備金 | G24: ='表3-1｜期入預算附屬表'!G26 -> 0 | H24: 0 | I24: ='表3-2｜期出預算附屬表'!G51 -> 2634.2105 | J24: ='表3-2｜期出預算附屬表'!H51 -> 0.05
B26: 3 | C26: 0 | D26: 0 | F26: 財務部 | G26: ='表3-1｜期入預算附屬表'!G28 -> 0 | H26: 0 | I26: ='表3-2｜期出預算附屬表'!G54 -> 22905 | J26: ='表3-2｜期出預算附屬表'!H54 -> 0.019347153
C28: 0 | D28: 1 | F28: 一般行政計畫 | G28: ='表3-1｜期入預算附屬表'!G30 -> 0 | H28: 0 | I28: ='表3-2｜期出預算附屬表'!G55 -> 21760 | J28: ='表3-2｜期出預算附屬表'!H55 -> 0.95001091
C29: 9 | D29: 9 | F29: 預備金 | G29: ='表3-1｜期入預算附屬表'!G31 -> 0 | H29: 0 | I29: ='表3-2｜期出預算附屬表'!G62 -> 1145 | J29: ='表3-2｜期出預算附屬表'!H62 -> 0.049989085
B31: 4 | C31: 0 | D31: 0 | F31: 學權部 | G31: 0 | H31: 0 | I31: ='表3-2｜期出預算附屬表'!G65 -> 33789.474 | J31: ='表3-2｜期出預算附屬表'!H65 -> 0.028540935
C33: 0 | D33: 1 | F33: 一般行政計畫 | G33: ='表3-1｜期入預算附屬表'!G35 -> 0 | H33: 0 | I33: ='表3-2｜期出預算附屬表'!G66 -> 32100 | J33: ='表3-2｜期出預算附屬表'!H66 -> 0.95
C34: 9 | D34: 9 | F34: 預備金 | G34: ='表3-1｜期入預算附屬表'!G36 -> 0 | H34: 0 | I34: ='表3-2｜期出預算附屬表'!G70 -> 1689.4737 | J34: ='表3-2｜期出預算附屬表'!H70 -> 0.05
B36: 5 | C36: 0 | D36: 0 | F36: 學術部 | G36: 0 | H36: 0 | I36: ='表3-2｜期出預算附屬表'!G73 -> 217811 | J36: ='表3-2｜期出預算附屬表'!H73 -> 0.18397829
C38: 0 | D38: 1 | F38: 一般行政計畫 | G38: ='表3-1｜期入預算附屬表'!G40 -> 0 | H38: 0 | I38: ='表3-2｜期出預算附屬表'!G75 -> 10000 | J38: ='表3-2｜期出預算附屬表'!H75 -> 0.045911364
C40: 1 | D40: 0 | F40: 性別工作坊 | G40: ='表3-1｜期入預算附屬表'!G42 -> 0 | H40: 0 | I40: ='表3-2｜期出預算附屬表'!G78 -> 70400 | J40: ='表3-2｜期出預算附屬表'!H78 -> 0.323216
D41: 1 | F41: 一般行政計畫 | G41: 0 | H41: 0 | I41: ='表3-2｜期出預算附屬表'!G79 -> 5000 | J41: ='表3-2｜期出預算附屬表'!H79 -> 0.071022727
D42: 2 | F42: 生理用品交換站暨月經議題倡議計畫 | G42: 0 | H42: 0 | I42: ='表3-2｜期出預算附屬表'!G81 -> 5930 | J42: ='表3-2｜期出預算附屬表'!H81 -> 0.084232955 | K42: ="會費支出："&(I42-G42) -> 會費支出：5930
D43: 3 | F43: NTU LGTBQ+ Community | G43: 0 | H43: 0 | I43: ='表3-2｜期出預算附屬表'!G85 -> 21020 | J43: ='表3-2｜期出預算附屬表'!H85 -> 0.29857955 | K43: ="會費支出："&(I43-G43) -> 會費支出：21020
D44: 4 | F44: 性別樹洞 | G44: 0 | H44: 0 | I44: ='表3-2｜期出預算附屬表'!G94 -> 5350 | J44: ='表3-2｜期出預算附屬表'!H94 -> 0.075994318 | K44: ="會費支出："&(I44-G44) -> 會費支出：5350
D45: 5 | F45: 節目製作【台大沒有愛那些大學戀情的坎坷與曲折，以及當今的性別議題】 | G45: 0 | H45: 0 | I45: ='表3-2｜期出預算附屬表'!G98 -> 33100 | J45: ='表3-2｜期出預算附屬表'!H98 -> 0.47017045 | K45: ="會費支出："&(I45-G45) -> 會費支出：33100
C47: 2 | D47: 0 | F47: 轉型正義組 | G47: ='表3-1｜期入預算附屬表'!G49 -> 0 | H47: 0 | I47: ='表3-2｜期出預算附屬表'!G106 -> 30470 | J47: ='表3-2｜期出預算附屬表'!H106 -> 0.13989192
D48: 1 | F48: 一般行政計畫 | G48: 0 | H48: 0 | I48: ='表3-2｜期出預算附屬表'!G107 -> 5000 | J48: ='表3-2｜期出預算附屬表'!H107 -> 0.16409583
D49: 2 | F49: 走讀活動【臺大記憶地圖：民主與自由的歷史軌跡】 | G49: 0 | H49: 0 | I49: ='表3-2｜期出預算附屬表'!G109 -> 7910 | J49: ='表3-2｜期出預算附屬表'!H109 -> 0.25959961 | K49: ="會費支出："&(I49-G49) -> 會費支出：7910
D50: 3 | F50: 讀書會【轉型正義讀書沙龍】 | G50: 0 | H50: 0 | I50: ='表3-2｜期出預算附屬表'!G120 -> 12030 | J50: ='表3-2｜期出預算附屬表'!H120 -> 0.39481457 | K50: ="會費支出："&(I50-G50) -> 會費支出：12030
D51: 4 | F51: 參訪活動【跟著轉型正義小組一同參訪去：景美白色恐怖人權園區】 | G51: 0 | H51: 0 | I51: ='表3-2｜期出預算附屬表'!G129 -> 1220 | J51: ='表3-2｜期出預算附屬表'!H129 -> 0.040039383 | K51: ="會費支出："&(I51-G51) -> 會費支出：1220
D52: 5 | F52: 社群經營【轉型正義小組社群經營】 | G52: 0 | H52: 0 | I52: ='表3-2｜期出預算附屬表'!G135 -> 4310 | J52: ='表3-2｜期出預算附屬表'!H135 -> 0.14145061 | K52: ="會費支出："&(I52-G52) -> 會費支出：4310
C54: 3 | D54: 0 | F54: 永續組 | G54: ='表3-1｜期入預算附屬表'!G56 -> 0 | H54: 0 | I54: ='表3-2｜期出預算附屬表'!G140 -> 56050 | J54: ='表3-2｜期出預算附屬表'!H140 -> 0.25733319
...

Sheet 表3-1｜期入預算附屬表
A1: 國立臺灣大學學生會總預算案
A2: 期入預算附屬表
A3: 第37屆第二期間（113-2）
A4: 2025年03月04日至2025年07月31日 | I4: 單位：新台幣元
A5: 單位計畫別 | E5: 預算科目 | G5: 本期間 | H5: 本期間 | I5: 說明 | J5: 委員會意見｜大會審議結果
A6: 款 | B6: 項 | C6: 目 | D6: 節 | E6: 代碼 | F6: 名稱 | G6: 預算數 | H6: 百分比
F7: 合計 | G7: =G9+G116+G130 -> 1898833 | H7: 1
A9: 1 | B9: 0 | C9: 0 | D9: 0 | F9: 行政部門 | G9: =G11+G23+G28+G33+G38+G73+G78+G83+G91+G105 -> 1898833 | H9: =G9/$G$7 -> 1
B11: 1 | C11: 0 | D11: 0 | F11: 會長 | G11: =G13+G19+G21 -> 1848833 | H11: =G11/$G$9 -> 0.97366804
C13: 0 | D13: 1 | F13: 一般行政計畫 | G13: =G14+G15 -> 1848833 | H13: =G13/$G$11 -> 1
E14: Z04 | F14: 公關贊助收入 | G14: 20000 | H14: =G14/$G$13 -> 0.010817635 | I14: 各類廠商贊助
E15: Z99 | F15: 前期轉入 | G15: 1828833 | H15: =G15/$G$13 -> 0.98918237 | I15: 第37-1屆期間總決算尚未編造及審議完成，依目前中信及郵局存簿餘額暫列為1,828,833元
C16: 0 | D16: 2 | F16: 2025春季招募計畫 | G16: 0 | H16: =G16/$G$11 -> 0
C17: 0 | D17: 3 | F17: 2025社團博覽會 | G17: 0 | H17: =G17/$G$11 -> 0
C18: 0 | D18: 4 | F18: 學生會全會交流計畫 | G18: 0 | H18: =G18/$G$11 -> 0
C19: 0 | D19: 5 | F19: 全校師生座談會計畫 | G19: 0 | H19: =G19/$G$11 -> 0
C20: 0 | D20: 6 | F20: 職棒會長來台大－職棒如何走向榮景及新球季展望 | G20: 0 | H20: =G20/$G$11 -> 0
C21: 9 | D21: 9 | F21: 預備金 | G21: 0 | H21: =G21/$G$11 -> 0
B23: 2 | C23: 0 | D23: 0 | F23: 秘書處 | G23: 0 | H23: =G23/$G$9 -> 0
C25: 0 | D25: 1 | F25: 一般行政計畫 | G25: 0 | H25: 0
C26: 9 | D26: 9 | F26: 預備金 | G26: 0 | H26: 0
B28: 3 | C28: 0 | D28: 0 | F28: 財務部 | G28: 0 | H28: =G28/$G$9 -> 0
C30: 0 | D30: 1 | F30: 一般行政計畫 | G30: 0 | H30: 0
C31: 9 | D31: 9 | F31: 預備金 | G31: 0 | H31: 0
B33: 4 | C33: 0 | D33: 0 | F33: 學權部 | G33: 0 | H33: =G33/$G$9 -> 0
C35: 0 | D35: 1 | F35: 一般行政計畫 | G35: 0 | H35: 0
C36: 9 | D36: 9 | F36: 預備金 | G36: 0 | H36: 0
B38: 5 | C38: 0 | D38: 0 | F38: 學術部 | G38: 0 | H38: =G38/$G$9 -> 0
C40: 0 | D40: 1 | F40: 一般行政計畫 | G40: 0 | H40: 0
C42: 1 | D42: 0 | F42: 性別工作坊 | G42: 0 | H42: 0
D43: 1 | F43: 一般行政計畫 | G43: 0 | H43: 0
D44: 2 | F44: 生理用品交換站暨月經議題倡議計畫 | G44: 0 | H44: 0
D45: 3 | F45: NTU LGTBQ+ Community | G45: 0 | H45: 0
D46: 4 | F46: 性別樹洞 | G46: 0 | H46: 0
D47: 5 | F47: 節目製作【台大沒有愛那些大學戀情的坎坷與曲折，以及當今的性別議題】 | G47: 0 | H47: 0
C49: 2 | D49: 0 | F49: 轉型正義組 | G49: 0 | H49: 0
D50: 1 | F50: 一般行政計畫 | G50: 0 | H50: 0
D51: 2 | F51: 走讀活動【臺大記憶地圖：民主與自由的歷史軌跡】 | G51: 0 | H51: 0
D52: 3 | F52: 讀書會【轉型正義讀書沙龍】 | G52: 0 | H52: 0
D53: 4 | F53: 參訪活動【跟著轉型正義小組一同參訪去：景美白色恐怖人權園區】 | G53: 0 | H53: 0
...

Sheet 表3-2｜期出預算附屬表
A1: 鐘點費
A2: 第37屆第二期間（113-2）
A3: 2025年03月04日至2025年07月31日
A4: 單位計畫別 | E4: 預算科目 | G4: 本期間 | H4: 本期間 | I4: 說明 | J4: 委員會意見｜大會審議結果
A5: 款 | B5: 項 | C5: 目 | D5: 節 | E5: 代碼 | F5: 名稱 | G5: 預算數 | H5: 百分比
F6: 合計 | G6: =G8+G333+G358 -> 1396063.7 | H6: 1
A8: 1 | B8: 0 | C8: 0 | D8: 0 | F8: 行政部門 | G8: =G10+G42+G54+G65+G73+G206+G217+G225+G257+G299 -> 1183895.1 | H8: =G8/$G$6 -> 0.84802371
B10: 1 | C10: 0 | D10: 0 | F10: 會長 | G10: =G11+G17+G20+G24+G29+G39+G33 -> 150568.42 | H10: =G10/$G$8 -> 0.12718054
C11: 0 | D11: 1 | F11: 一般行政計畫 | G11: =SUM(G12:G16) -> 80410 | H11: =G11/$G$10 -> 0.53404293
E12: A02 | F12: 工作費 | G12: 35910 | H12: =G12/$G$11 -> 0.44658625 | I12: (1)會長、兩位副會長工作費：每小時190元，以每週3小時計，共21週，共3名，總計35,910元。
E13: B01 | F13: 行政費 | G13: 15000 | H13: =G13/$G$11 -> 0.18654396 | I13: (1)會長、兩位副會長行政費，1000元/月*5個月*3人=15,000元。
E14: B02 | F14: 誤餐費 | G14: 28000 | H14: =G14/$G$11 -> 0.3482154 | I14: (1)幹部會議誤餐費，每位100元，共20位，共14次，總計28,000元
E15: B05 | F15: 印刷費 | G15: 1000 | H15: =G15/$G$11 -> 0.012436264 | I15: (1)臨時需印製各類文件、海報之費用。
E16: B99 | F16: 雜支 | G16: 500 | H16: =G16/$G$11 -> 0.0062181321 | I16: (1)臨時需製作美工、購買用具之費用。
C17: 0 | D17: 2 | F17: 2025春季招募計畫 | G17: =SUM(G18:G19) -> 3300 | H17: =G17/$G$10 -> 0.021916946
E18: B05 | F18: 印刷費 | G18: 500 | H18: =G18/$G$17 -> 0.15151515 | I18: (1)印製招生海報費用
E19: B06 | F19: 場地費 | G19: 2800 | H19: =G19/$G$17 -> 0.84848485 | I19: (1) 教室借用費：700/次，4次，共2,800元。
C20: 0 | D20: 3 | F20: 2025社團博覽會 | G20: =SUM(G21:G23) -> 7880 | H20: =G20/$G$10 -> 0.052335011
E21: A01 | F21: 臨時工資 | G21: 6080 | H21: =G21/$G$20 -> 0.7715736 | I21: (1) 攤位工作人員：190元/時，預計8人，4時/人，共6,080元。
E22: B02 | F22: 誤餐費 | G22: 800 | H22: =G22/$G$20 -> 0.10152284 | I22: (1) 攤位工作人員餐費，每人100，預計8人，總計800元
E23: B06 | F23: 場地費 | G23: 1000 | H23: =G23/$G$20 -> 0.12690355 | I23: (1)場地費，租借攤位(不用電)，1000/攤
C24: 0 | D24: 4 | F24: 學生會全會交流計畫 | G24: =SUM(G25:G28) -> 14100 | H24: =G24/$G$10 -> 0.093645134
E25: A04 | F25: 鐘點費 | G25: 6000 | H25: =G25/$G$24 -> 0.42553191 | I25: (1)講師費：部內幹部介紹自己部內事務，每人500元，預計12人，總計6,000元。
E26: B03 | F26: 茶點費 | G26: 4800 | H26: =G26/$G$24 -> 0.34042553 | I26: (1)茶點費：會內交流活動之茶點，每人80元預計60人，總計4,800元。
E27: B06 | F27: 場地費 | G27: 2800 | H27: =G27/$G$24 -> 0.19858156 | I27: (1) 沃思借用費：2,800/次，1次，共2,800元。
E28: B99 | F28: 雜支 | G28: 500 | H28: =G28/$G$24 -> 0.035460993 | I28: (1)交流所需文具費
C29: 0 | D29: 5 | F29: 全校師生座談會計畫 | G29: =SUM(G30:G32) -> 19050 | H29: =G29/$G$10 -> 0.12652055
E30: A02 | F30: 工作費 | G30: 2850 | H30: =G30/$G$29 -> 0.1496063 | I30: (1)事前籌辦及現場工作人員，每小時190元，以15小時計，共2,850元。
E31: B02 | F31: 餐費 | G31: 15000 | H31: =G31/$G$29 -> 0.78740157 | I31: (1)100元/人，共150人，總計15,000元。
E32: B05 | F32: 印刷費 | G32: 1200 | H32: =G32/$G$29 -> 0.062992126 | I32: (1)海報300元/張，共4張，1,200元。
C33: 0 | D33: 6 | F33: 職棒會長來台大－職棒如何走向榮景及新球季展望 | G33: =SUM(G34:G38) -> 18300 | H33: =G33/$G$10 -> 0.12153943
E34: A01 | F34: 臨時工資 | G34: 6080 | H34: =G34/$G$33 -> 0.33224044 | I34: 工作人數 8 人，以法定基本工資每小時190 元計，總共 4*8*190=6,080 元。
E35: A04 | G35: 4000 | H35: =G35/$G$33 -> 0.21857924 | I35: 邀請兩位講師，每位2000元，總共4,000元
E36: B02 | F36: 誤餐費 | G36: 240 | H36: =G36/$G$33 -> 0.013114754 | I36: 講師及其助理餐費，共3位，每位80元，總共240元
E37: B06 | F37: 場地費 | G37: 7500 | H37: =G37/$G$33 -> 0.40983607 | I37: 預計租借博雅教學館102教室，共一間，共 7,500*1=7,500 元。
E38: B99 | F38: 雜支 | G38: 480 | H38: =G38/$G$33 -> 0.026229508 | I38: 活動雜項支出，總共480元
C39: 9 | D39: 9 | F39: 預備金 | G39: =(G11+G17+G20+G24+G29+G33)/95*5 -> 7528.4211 | H39: =G39/$G$10 -> 0.05 | I39: 依預算法編列單位預算 5%。
B42: 2 | C42: 0 | D42: 0 | F42: 秘書處 | G42: =G43+G51 -> 52684.211 | H42: =G42/$G$8 -> 0.044500742
C43: 0 | D43: 1 | F43: 一般行政計畫 | G43: =SUM(G44:G50) -> 50050 | H43: =G43/$G$42 -> 0.95
E44: A02 | F44: 工作費 | G44: 10450 | H44: =G44/$G$43 -> 0.20879121 | I44: (1) 活動場地組：預計25小時(2) 空間財產組：預計25小時(3) 文書檔案組：預計5小時，190元/時，55小時，共10,450元。
...

Sheet 可以砍的地方
A1: 1201 | B1: A02 | C1: 16800 | E1: 返鄉專車 | F1: 20-30萬
A2: 1301 | B2: B03 | C2: 3040 | E2: 校慶 | F2: 45000 | G2: 跟院學生會合辦
B3: B10 | C3: 300 | G3: 攤位 帳篷
A4: 1402 | C4: 6500
A5: 1432 | C5: 6800
A6: 1613 | C6: 15000
A7: 1633 | C7: 15000
C12: =SUM(C1:C11) -> 63440
