Workbook

Sheet 表1｜綜計表
A1: 國立臺灣大學學生會總預算案
A2: 綜計表
A3: 第38屆第一期間（114-1）
A4: 2025年9月22日至2026年3月14日 | I4: 單位：新台幣元
A5: 單位別 | F5: 本期間期入 | G5: 佔本期間期入 | H5: 本期間期出 | I5: 佔本期間期出
A6: 款 | B6: 項 | C6: 說明 | F6: 預算數 | G6: 百分比 | H6: 預算數 | I6: 百分比
C7: 合計 | F7: ='表2｜主要表'!G7 -> 2591697 | G7: =F7/F7 -> 1 | H7: =H9+H21+H24 -> 1843758.2 | I7: =H7/H7 -> 1
A9: 1 | B9: 0 | C9: 行政部門 | F9: ='表2｜主要表'!G9 -> 2591697 | G9: ='表2｜主要表'!H9 -> 1 | H9: ='表2｜主要表'!I9 -> 1565084.3 | I9: ='表2｜主要表'!J9 -> 0.84885551
B10: 1 | C10: 會長 | F10: ='表2｜主要表'!G11 -> 2095497 | G10: ='表2｜主要表'!H11 -> 0.80854243 | H10: ='表2｜主要表'!I11 -> 126421.05 | I10: ='表2｜主要表'!J11 -> 0.080775873
B11: 2 | C11: 秘書處 | F11: 0 | G11: ='表2｜主要表'!H17 -> 0 | H11: ='表2｜主要表'!I17 -> 84105.263 | I11: ='表2｜主要表'!J17 -> 0.053738487
B12: 3 | C12: 財務部 | F12: ='表2｜主要表'!G22 -> 0 | G12: ='表2｜主要表'!H22 -> 0 | H12: ='表2｜主要表'!I22 -> 24053 | I12: ='表2｜主要表'!J22 -> 0.015368501
B13: 4 | C13: 學權部 | F13: ='表2｜主要表'!G27 -> 220000 | G13: ='表2｜主要表'!H27 -> 0.084886466 | H13: ='表2｜主要表'!I27 -> 273054 | I13: ='表2｜主要表'!J27 -> 0.174466
B14: 5 | C14: 學術部 | F14: 0 | G14: ='表2｜主要表'!H33 -> 0 | H14: ='表2｜主要表'!I33 -> 160316 | I14: ='表2｜主要表'!J33 -> 0.10243282
B15: 6 | C15: 文化部 | F15: ='表2｜主要表'!G61 -> 160000 | G15: ='表2｜主要表'!H61 -> 0.061735612 | H15: ='表2｜主要表'!I61 -> 252806 | I15: ='表2｜主要表'!J61 -> 0.16152868
B16: 7 | C16: 公關部 | F16: ='表2｜主要表'!G70 -> 0 | G16: ='表2｜主要表'!H70 -> 0 | H16: ='表2｜主要表'!I70 -> 36316 | I16: ='表2｜主要表'!J70 -> 0.023203862
B17: 8 | C17: 選舉罷免執行委員會 | F17: ='表2｜主要表'!G76 -> 50000 | G17: ='表2｜主要表'!H76 -> 0.019292379 | H17: ='表2｜主要表'!I76 -> 409202 | I17: ='表2｜主要表'!J76 -> 0.26145684
B18: 9 | C18: 國際事務部 | F18: ='表2｜主要表'!G83 -> 66200 | G18: ='表2｜主要表'!H83 -> 0.025543109 | H18: ='表2｜主要表'!I83 -> 110474 | I18: ='表2｜主要表'!J83 -> 0.070586612
B19: A | C19: 資訊部 | F19: ='表2｜主要表'!G95 -> 0 | G19: ='表2｜主要表'!H95 -> 0 | H19: ='表2｜主要表'!I95 -> 88337 | I19: ='表2｜主要表'!J95 -> 0.056442327
A21: 2 | B21: 0 | C21: 立法部門 | F21: ='表2｜主要表'!G104 -> 0 | G21: ='表2｜主要表'!H104 -> 0 | H21: ='表2｜主要表'!I104 -> 184316 | I21: ='表2｜主要表'!J104 -> 0.099967555
B22: 1 | C22: 學生代表大會 | F22: ='表2｜主要表'!G105 -> 0 | G22: ='表2｜主要表'!H105 -> 0 | H22: ='表2｜主要表'!I105 -> 184316 | I22: ='表2｜主要表'!J105 -> 1
A24: 3 | B24: 0 | C24: 司法部門 | F24: ='表2｜主要表'!G112 -> 0 | G24: ='表2｜主要表'!H112 -> 0 | H24: ='表2｜主要表'!I112 -> 94357.895 | I24: ='表2｜主要表'!J112 -> 0.051176935
B25: 1 | C25: 學生法院 | F25: ='表2｜主要表'!G113 -> 0 | G25: ='表2｜主要表'!H113 -> 0 | H25: ='表2｜主要表'!I113 -> 94357.895 | I25: ='表2｜主要表'!J113 -> 1
A27: 款 | C27: 部門預算
A28: 項 | C28: 單位預算
A29: 目 | C29: 附屬單位預算
A30: 節 | C30: 計畫名稱

Sheet 表2｜主要表
A1: 國立臺灣大學學生會總預算案
A2: 主要表
A3: 第38屆第一期間（114-1）
A4: 2025年9月22日至2026年3月14日
A5: 單位計畫別 | E5: 預算科目 | G5: 本期期入 | I5: 本期期出 | K5: 各計畫會費支出情形
A6: 款 | B6: 項 | C6: 目 | D6: 節 | E6: 代碼 | F6: 名稱 | G6: 預算數 | I6: 預算數
F7: 合計 | G7: =G9+G104+G112 -> 2591697 | H7: =G7/G7 -> 1 | I7: ='表3-2｜期出預算附屬表'!G6 -> 1843758.2 | J7: =I7/I7 -> 1
A9: 1 | B9: 0 | C9: 0 | D9: 0 | F9: 行政部門 | G9: ='表3-1｜期入預算附屬表'!G9 -> 2591697 | H9: =G9/G7 -> 1 | I9: ='表3-2｜期出預算附屬表'!G8 -> 1565084.3 | J9: ='表3-2｜期出預算附屬表'!H8 -> 0.84885551
B11: 1 | C11: 0 | D11: 0 | F11: 會長 | G11: ='表3-1｜期入預算附屬表'!G11 -> 2095497 | H11: =G11/G9 -> 0.80854243 | I11: ='表3-2｜期出預算附屬表'!G10 -> 126421.05 | J11: ='表3-2｜期出預算附屬表'!H10 -> 0.080775873
C13: 0 | D13: 1 | F13: 一般行政計畫 | G13: ='表3-1｜期入預算附屬表'!G13 -> 2095497 | H13: =G13/G7 -> 0.80854243 | I13: ='表3-2｜期出預算附屬表'!G11 -> 104700 | J13: ='表3-2｜期出預算附屬表'!H11 -> 0.82818485
C14: 0 | D14: 2 | F14: Line官方帳號計畫 | G14: 0 | H14: 0 | I14: 15400 | J14: ='表3-2｜期出預算附屬表'!H20 -> 0.12181515 | K14: ="會費支出："&(I14-G14) -> 會費支出：15400
C15: 9 | D15: 9 | F15: 預備金 | G15: ='表3-1｜期入預算附屬表'!G18 -> 0 | H15: 0 | I15: ='表3-2｜期出預算附屬表'!G25 -> 6321.0526 | J15: ='表3-2｜期出預算附屬表'!H25 -> 0.05
B17: 2 | C17: 0 | D17: 0 | F17: 秘書處 | G17: 0 | H17: 0 | I17: ='表3-2｜期出預算附屬表'!G29 -> 84105.263 | J17: ='表3-2｜期出預算附屬表'!H29 -> 0.053738487
C19: 0 | D19: 1 | F19: 一般行政計畫 | G19: ='表3-1｜期入預算附屬表'!G22 -> 0 | H19: 0 | I19: ='表3-2｜期出預算附屬表'!G30 -> 79900 | J19: ='表3-2｜期出預算附屬表'!H30 -> 0.95
C20: 9 | D20: 9 | F20: 預備金 | G20: ='表3-1｜期入預算附屬表'!G23 -> 0 | H20: 0 | I20: ='表3-2｜期出預算附屬表'!G44 -> 4205.2632 | J20: ='表3-2｜期出預算附屬表'!H44 -> 0.05
B22: 3 | C22: 0 | D22: 0 | F22: 財務部 | G22: ='表3-1｜期入預算附屬表'!G25 -> 0 | H22: 0 | I22: ='表3-2｜期出預算附屬表'!G48 -> 24053 | J22: ='表3-2｜期出預算附屬表'!H48 -> 0.015368501
C24: 0 | D24: 1 | F24: 一般行政計畫 | G24: ='表3-1｜期入預算附屬表'!G27 -> 0 | H24: 0 | I24: ='表3-2｜期出預算附屬表'!G49 -> 22850 | J24: ='表3-2｜期出預算附屬表'!H49 -> 0.94998545
C25: 9 | D25: 9 | F25: 預備金 | G25: ='表3-1｜期入預算附屬表'!G28 -> 0 | H25: 0 | I25: ='表3-2｜期出預算附屬表'!G57 -> 1203 | J25: ='表3-2｜期出預算附屬表'!H57 -> 0.050014551
B27: 4 | C27: 0 | D27: 0 | F27: 學權部 | G27: ='表3-1｜期入預算附屬表'!G30 -> 220000 | H27: ='表3-1｜期入預算附屬表'!H30 -> 0.084886466 | I27: =SUM(I29:I31) -> 273054 | J27: ='表3-2｜期出預算附屬表'!H61 -> 0.174466
C29: 0 | D29: 1 | F29: 一般行政計畫 | G29: ='表3-1｜期入預算附屬表'!G32 -> 0 | H29: 0 | I29: ='表3-2｜期出預算附屬表'!G62 -> 22700 | J29: ='表3-2｜期出預算附屬表'!H62 -> 0.083133739
C30: 0 | D30: 2 | F30: 臺灣大學花蓮光復賑災補助計劃 | G30: ='表3-1｜期入預算附屬表'!G33 -> 220000 | H30: ='表3-1｜期入預算附屬表'!H33 -> 1 | I30: ='表3-2｜期出預算附屬表'!G66 -> 236701 | J30: ='表3-2｜期出預算附屬表'!H66 -> 0.86686516 | K30: ="會費支出："&(I30-G30) -> 會費支出：16701
C31: 9 | D31: 9 | F31: 預備金 | G31: ='表3-1｜期入預算附屬表'!G39 -> 0 | H31: 0 | I31: ='表3-2｜期出預算附屬表'!G70 -> 13653 | J31: ='表3-2｜期出預算附屬表'!H70 -> 0.050001099
B33: 5 | C33: 0 | D33: 0 | F33: 學術部 | G33: 0 | H33: 0 | I33: ='表3-2｜期出預算附屬表'!G74 -> 160316 | J33: ='表3-2｜期出預算附屬表'!H74 -> 0.10243282
C35: 0 | D35: 1 | F35: 一般行政計畫 | G35: ='表3-1｜期入預算附屬表'!G43 -> 0 | H35: 0 | I35: ='表3-2｜期出預算附屬表'!G75 -> 3000 | J35: ='表3-2｜期出預算附屬表'!H75 -> 0.018713042
C36: 1 | D36: 0 | F36: 性別平等工作坊 | G36: ='表3-1｜期入預算附屬表'!G45 -> 0 | H36: 0 | I36: ='表3-2｜期出預算附屬表'!G78 -> 52220 | J36: ='表3-2｜期出預算附屬表'!H78 -> 0.32573168
D37: 1 | F37: 一般行政計畫 | G37: 0 | H37: 0 | I37: ='表3-2｜期出預算附屬表'!G79 -> 3000 | J37: ='表3-2｜期出預算附屬表'!H79 -> 0.057449253
D38: 2 | F38: 生理用品交換站暨月經議題倡議計畫 | G38: 0 | H38: 0 | I38: ='表3-2｜期出預算附屬表'!G81 -> 5820 | J38: ='表3-2｜期出預算附屬表'!H81 -> 0.11145155 | K38: ="會費支出："&(I38-G38) -> 會費支出：5820
D39: 3 | F39: 性別樹洞 | G39: 0 | H39: 0 | I39: ='表3-2｜期出預算附屬表'!G85 -> 6700 | J39: ='表3-2｜期出預算附屬表'!H85 -> 0.12830333 | K39: ="會費支出："&(I39-G39) -> 會費支出：6700
D40: 4 | F40: 台大校內同志大遊行 | G40: 0 | H40: 0 | I40: ='表3-2｜期出預算附屬表'!G89 -> 16800 | J40: ='表3-2｜期出預算附屬表'!H89 -> 0.32171582 | K40: ="會費支出："&(I40-G40) -> 會費支出：16800
D41: 5 | F41: 專欄文章藉親密關係面向及女性主義視角 | G41: 0 | H41: 0 | I41: ='表3-2｜期出預算附屬表'!G100 -> 10000 | J41: ='表3-2｜期出預算附屬表'!H100 -> 0.19149751 | K41: ="會費支出："&(I41-G41) -> 會費支出：10000
D42: 6 | F42: 愛在校園蔓延時_性工坊午餐live podcast活動 | G42: 0 | H42: 0 | I42: ='表3-2｜期出預算附屬表'!G104 -> 9900 | J42: ='表3-2｜期出預算附屬表'!H104 -> 0.18958254 | K42: ="會費支出："&(I42-G42) -> 會費支出：9900
C44: 2 | D44: 0 | F44: 轉型正義組 | G44: ='表3-1｜期入預算附屬表'!G53 -> 0 | H44: 0 | I44: ='表3-2｜期出預算附屬表'!G112 -> 26780 | J44: ='表3-2｜期出預算附屬表'!H112 -> 0.16704509
D45: 1 | F45: 一般行政計畫 | G45: 0 | H45: 0 | I45: ='表3-2｜期出預算附屬表'!G113 -> 3000 | J45: ='表3-2｜期出預算附屬表'!H113 -> 0.1120239
D46: 2 | F46: 社群經營【轉型正義小組社群經營】 | G46: 0 | H46: 0 | I46: ='表3-2｜期出預算附屬表'!G115 -> 12380 | J46: ='表3-2｜期出預算附屬表'!H115 -> 0.46228529 | K46: ="會費支出："&(I46-G46) -> 會費支出：12380
D47: 3 | F47: 走讀活動【白恐電影賞析：人權奮鬥的記憶傳承】 | G47: 0 | H47: 0 | I47: ='表3-2｜期出預算附屬表'!G121 -> 11400 | J47: ='表3-2｜期出預算附屬表'!H121 -> 0.42569081 | K47: ="會費支出："&(I47-G47) -> 會費支出：11400
C49: 3 | D49: 0 | F49: 永續組 | G49: ='表3-1｜期入預算附屬表'!G57 -> 0 | H49: 0 | I49: ='表3-2｜期出預算附屬表'!G130 -> 29900 | J49: ='表3-2｜期出預算附屬表'!H130 -> 0.18650665
D50: 1 | F50: 一般行政計畫 | G50: 0 | H50: 0 | I50: ='表3-2｜期出預算附屬表'!G131 -> 3000 | J50: ='表3-2｜期出預算附屬表'!H131 -> 0.10033445
D51: 2 | F51: 從剩食減量到永續發展：校園綠色行動計畫 | G51: 0 | H51: 0 | I51: ='表3-2｜期出預算附屬表'!G133 -> 26900 | J51: ='表3-2｜期出預算附屬表'!H133 -> 0.89966555 | K51: ="會費支出："&(I51-G51) -> 會費支出：26900
C53: 4 | D53: 0 | F53: 本土語言小組 | G53: ='表3-1｜期入預算附屬表'!G62 -> 0 | H53: 0 | I53: ='表3-2｜期出預算附屬表'!G143 -> 40400 | J53: ='表3-2｜期出預算附屬表'!H143 -> 0.2520023
D54: 1 | F54: 一般行政計畫 | G54: 0 | H54: 0 | I54: ='表3-2｜期出預算附屬表'!G144 -> 3000 | J54: ='表3-2｜期出預算附屬表'!H144 -> 0.074257426
...

Sheet 表3-1｜期入預算附屬表
A1: 國立臺灣大學學生會總預算案
A2: 期入預算附屬表
A3: 第38屆第一期間（114-1）
A4: 2025年9月22日至2026年3月14日 | I4: 單位：新台幣元
A5: 單位計畫別 | E5: 預算科目 | G5: 本期間 | H5: 本期間 | I5: 說明 | J5: 委員會意見｜大會審議結果
A6: 款 | B6: 項 | C6: 目 | D6: 節 | E6: 代碼 | F6: 名稱 | G6: 預算數 | H6: 百分比
F7: 合計 | G7: =G9+G127+G141 -> 2591697 | H7: 1
A9: 1 | B9: 0 | C9: 0 | D9: 0 | F9: 行政部門 | G9: =G11+G20+G25+G30+G41+G71+G89+G96+G104+G118 -> 2591697 | H9: =G9/$G$7 -> 1
B11: 1 | C11: 0 | D11: 0 | F11: 會長 | G11: =G13+G18 -> 2095497 | H11: =G11/$G$9 -> 0.80854243
C13: 0 | D13: 1 | F13: 一般行政計畫 | G13: =SUM(G14:G16) -> 2095497 | H13: =G13/$G$11 -> 1
E14: Z01 | F14: 會費收入 | G14: 1217715 | H14: =G14/$G$13 -> 0.58111035 | I14: 依目前中信帳戶撥款數字列數。
E15: Z04 | F15: 公關贊助收入 | G15: 0 | H15: =G15/$G$13 -> 0
E16: Z99 | F16: 前期轉入 | G16: 877782 | H16: =G16/$G$13 -> 0.41888965 | I16: 依中信、郵局截至9/22帳列數
C18: 9 | D18: 9 | F18: 預備金 | G18: 0 | H18: =G18/$G$11 -> 0
B20: 2 | C20: 0 | D20: 0 | F20: 秘書處 | G20: 0 | H20: =G20/$G$9 -> 0
C22: 0 | D22: 1 | F22: 一般行政計畫 | G22: 0 | H22: 0
C23: 9 | D23: 9 | F23: 預備金 | G23: 0 | H23: 0
B25: 3 | C25: 0 | D25: 0 | F25: 財務部 | G25: 0 | H25: =G25/$G$9 -> 0
C27: 0 | D27: 1 | F27: 一般行政計畫 | G27: 0 | H27: 0
C28: 9 | D28: 9 | F28: 預備金 | G28: 0 | H28: 0
B30: 4 | C30: 0 | D30: 0 | F30: 學權部 | G30: =G33 -> 220000 | H30: =G30/$G$9 -> 0.084886466
C32: 0 | D32: 1 | F32: 一般行政計畫 | G32: 0 | H32: 0
C33: 0 | D33: 2 | F33: 臺灣大學花蓮光復賑災補助計劃 | G33: =SUM(G34:G37) -> 220000 | H33: 1
E34: Z05 | F34: 贊助— 校方 | G34: 100000 | H34: =G34/$G$33 -> 0.45454545 | I34: 待審核
E35: Z05 | F35: 贊助— 領導學程 呂芳銘老師 | G35: 100000 | H35: =G35/$G$33 -> 0.45454545 | I35: 待審核
E36: Z05 | F36: 贊助— 陳志榮先生 | G36: 5000 | H36: =G36/$G$33 -> 0.022727273
E37: Z05 | F37: 贊助— 扶輪青年社 | G37: 15000 | H37: =G37/$G$33 -> 0.068181818
C39: 9 | D39: 9 | F39: 預備金 | G39: 0 | H39: 0
B41: 5 | C41: 0 | D41: 0 | F41: 學術部 | G41: 0 | H41: =G41/$G$9 -> 0
C43: 0 | D43: 1 | F43: 一般行政計畫 | G43: 0 | H43: 0
C45: 1 | D45: 0 | F45: 性別平等工作坊 | G45: 0 | H45: 0
D46: 1 | F46: 一般行政計畫 | G46: 0 | H46: 0
D47: 2 | F47: 生理用品交換站暨月經議題倡議計畫 | G47: 0 | H47: 0
D48: 3 | F48: 性別樹洞 | G48: 0 | H48: 0
D49: 4 | F49: 台大校內同志大遊行 | G49: 0 | H49: 0
D50: 5 | F50: 專欄文章藉親密關係面向及女性主義視角 | G50: 0 | H50: 0
D51: 6 | F51: 愛在校園蔓延時_性工坊午餐live podcast活動 | G51: 0 | H51: 0
C53: 2 | D53: 0 | F53: 轉型正義組 | G53: 0 | H53: 0
D54: 1 | F54: 一般行政計畫 | G54: 0 | H54: 0
D55: 2 | F55: 社群經營【轉型正義小組社群經營】 | G55: 0 | H55: 0
...

Sheet 表3-2｜期出預算附屬表
A1: 國立臺灣大學學生會總預算案
A2: 期出預算附屬表
A3: 第38屆第一期間（114-1）
A4: 單位計畫別 | E4: 預算科目 | G4: 本期間 | H4: 本期間 | I4: 說明 | J4: 委員會意見｜大會審議結果
A5: 款 | B5: 項 | C5: 目 | D5: 節 | E5: 代碼 | F5: 名稱 | G5: 預算數 | H5: 百分比
F6: 合計 | G6: =G8+G347+G395 -> 1843758.2 | H6: 1
A8: 1 | B8: 0 | C8: 0 | D8: 0 | F8: 行政部門 | G8: =G10+G29+G48+G61+G74+G171+G211+G225+G269+G321 -> 1565084.3 | H8: =G8/$G$6 -> 0.84885551
B10: 1 | C10: 0 | D10: 0 | F10: 會長 | G10: =G11+G25+G20 -> 126421.05 | H10: =G10/$G$8 -> 0.080775873
C11: 0 | D11: 1 | F11: 一般行政計畫 | G11: =SUM(G12:G18) -> 104700 | H11: =G11/$G$10 -> 0.82818485
E12: A02 | F12: 工作費 | G12: 55200 | H12: =G12/$G$11 -> 0.52722063 | I12: 副會長工作費：每小時 200 元，以每週 3小時計，共 23 週，共 2 名。共計200*3*23*2=27,600元。
I13: 會長秘書工作費：每小時 200 元，以每週 3 小時計，共 23 週，共 2 名。共計200*3*23*2=27,600元。
E14: B01 | F14: 行政費 | G14: 18000 | H14: =G14/$G$11 -> 0.17191977 | I14: 依作業要點編列，會長、兩位副會長行政費，本期間以6個月計算，1,000元 / 月。共計1,000*6*3=18,000元
E15: B05 | F15: 印刷費 | G15: 1000 | H15: =G15/$G$11 -> 0.0095510984 | I15: 臨時需印製各類文件、海報之費用。
E16: B20 | F16: 委辦費 | G16: 15000 | H16: =G16/$G$11 -> 0.14326648 | I16: 承接 37-3 活大 237 會辦垃圾清運效益有所成果，本會期預計進一步請打掃公司清掃活大 237 空間將此空間之討論功能效益進一步擴展，同時為對應解決牆壁粉刷剝落之情形進行相關牆壁粉刷之維護任務。此外，也針對大一女地下室之學生會空間，一併進行垃圾清運與空間清掃之任務。
E17: B99 | F17: 雜支 | G17: 500 | H17: =G17/$G$11 -> 0.0047755492 | I17: 依作業要點編列，每一計畫不超過500元。
E18: C01 | F18: 設備費 | G18: 15000 | H18: =G18/$G$11 -> 0.14326648 | I18: (1) 擬添購會辦投影機，共10,000元。
I19: (2) 擬添購會辦水冷氣，共5,000元。
C20: 0 | D20: 2 | F20: Line官方帳號計畫 | G20: =SUM(G21:G23) -> 15400 | H20: =G20/G10 -> 0.12181515
E21: A02 | F21: 工作費 | G21: 9600 | H21: =G21/G20 -> 0.62337662 | I21: 帳號經營費用：每小時工資200元，每月工時8小時，共6個月。共計200*8*6=9,600元。
E22: B08 | F22: 廣告費 | G22: 1000 | H22: =G22/G20 -> 0.064935065 | I22: 線下宣傳：海報與立板印製，共4張，估計1,000元。
E23: B12 | F23: 資訊服務使用費 | G23: 4800 | H23: =G23/G20 -> 0.31168831 | I23: Line官方帳號月費：使用中用量服務，估計4,800元
C25: 9 | D25: 9 | F25: 預備金 | G25: =(G11+G20)/95*5 -> 6321.0526 | H25: =G25/G10 -> 0.05 | I25: 依預算法編列單位預算 5%。
B29: 2 | C29: 0 | D29: 0 | F29: 秘書處 | G29: =G30+G44 -> 84105.263 | H29: =G29/$G$8 -> 0.053738487
C30: 0 | D30: 1 | F30: 一般行政計畫 | G30: =SUM(G31:G43) -> 79900 | H30: =G30/$G$29 -> 0.95
E31: A02 | F31: 工作費 | G31: 20000 | H31: =G31/$G$30 -> 0.25031289 | I31: (1) 活動場地組：預計60小時
I32: (2) 空間財產組：預計30小時
I33: (3) 文書檔案組：預計10小時
I34: 每小時200元，共100小時，共計200*100=20,000元。
E35: B01 | F35: 行政費 | G35: 3000 | H35: =G35/$G$30 -> 0.037546934 | I35: 依作業要點編列，本期間以6個月計算，500元 / 月。共計500*6=3,000元
E36: B04 | F36: 耗材費 | G36: 3000 | H36: =G36/$G$30 -> 0.037546934 | I36: 預計作為全會耗材購置使用
E37: B05 | F37: 印刷費 | G37: 300 | H37: =G37/$G$30 -> 0.0037546934 | I37: 作為場地活動申請文件之印刷費
E38: B06 | F38: 場地費 | G38: 30000 | H38: =G38/$G$30 -> 0.37546934 | I38: 各部門例會之場地費，本會期擬開例會之部門為資訊部、國際部、學術部轉型正義小組、學術部性別平等工作坊、學術部本土語言小組、文化部台大電影節
E39: B14 | F39: 手續費 | G39: 100 | H39: =G39/$G$30 -> 0.0012515645 | I39: 匯款給承包廠商之手續費用
E40: B15 | F40: 設備租借費 | G40: 8000 | H40: =G40/$G$30 -> 0.10012516 | I40: 租用設備臨時使用之費用
E41: B99 | F41: 雜支 | G41: 500 | H41: =G41/$G$30 -> 0.0062578223 | I41: 依作業要點編列，每一計畫不超過 500 元。
E42: C01 | F42: 設備費 | G42: 10000 | H42: =G42/$G$30 -> 0.12515645 | I42: 設備維修添購，老舊物品汰換
E43: C02 | F43: 修繕費 | G43: 5000 | H43: =G43/$G$30 -> 0.062578223 | I43: 擬維修會辦內MA-708擴音器
C44: 9 | D44: 9 | F44: 預備金 | G44: =(G30)/95*5 -> 4205.2632 | H44: =G44/$G$29 -> 0.05 | I44: 依預算法編列單位預算 5%。
B48: 3 | C48: 0 | D48: 0 | F48: 財務部 | G48: =G49+G57 -> 24053 | H48: =G48/$G$8 -> 0.015368501
C49: 0 | D49: 1 | F49: 一般行政計畫 | G49: =SUM(G50:G56) -> 22850 | H49: =G49/$G$48 -> 0.94998545
...

Sheet 可以砍的地方
A1: 1201 | B1: A02 | C1: 16800 | E1: 返鄉專車 | F1: 20-30萬
A2: 1301 | B2: B03 | C2: 3040 | E2: 校慶 | F2: 45000 | G2: 跟院學生會合辦
B3: B10 | C3: 300 | G3: 攤位 帳篷
A4: 1402 | C4: 6500
A5: 1432 | C5: 6800
A6: 1613 | C6: 15000
A7: 1633 | C7: 15000
C12: =SUM(C1:C11) -> 63440
