Workbook

Sheet 表1｜綜計表
A1: 國立臺灣大學學生會決算案
A2: 綜計表
A3: 第38屆第一期間（114-1）
A4: 2025年9月22日至2026年3月15日
A5: 單位別 | F5: 本期間期入 | G5: 佔本期間期入 | H5: 本期間期出 | I5: 佔本期間期出
A6: 款 | B6: 項 | C6: 說明 | F6: 決算數 | G6: 百分比 | H6: 決算數 | I6: 百分比
C7: 合計 | F7: ='表2｜主要表'!G7 -> 2439553 | G7: =F7/F7 -> 1 | H7: =H9+H21+H24 -> 1193805 | I7: =H7/H7 -> 1
A9: 1 | B9: 0 | C9: 行政部門 | F9: ='表2｜主要表'!G9 -> 2439553 | G9: ='表2｜主要表'!H9 -> 1 | H9: ='表2｜主要表'!I9 -> 1006930 | I9: ='表2｜主要表'!J9 -> 0.84346271
B10: 1 | C10: 會長 | F10: ='表2｜主要表'!G11 -> 2133763 | G10: ='表2｜主要表'!H11 -> 0.87465327 | H10: ='表2｜主要表'!I11 -> 48600 | I10: ='表2｜主要表'!J11 -> 0.04826552
B11: 2 | C11: 秘書處 | F11: 0 | G11: ='表2｜主要表'!H17 -> 0 | H11: ='表2｜主要表'!I17 -> 56943 | I11: ='表2｜主要表'!J17 -> 0.056551101
B12: 3 | C12: 財務部 | F12: ='表2｜主要表'!G22 -> 0 | G12: ='表2｜主要表'!H22 -> 0 | H12: ='表2｜主要表'!I22 -> 28050 | I12: ='表2｜主要表'!J22 -> 0.027856951
B13: 4 | C13: 學權部 | F13: ='表2｜主要表'!G27 -> 109104 | G13: ='表2｜主要表'!H27 -> 0.044722947 | H13: ='表2｜主要表'!I27 -> 142954 | I13: ='表2｜主要表'!J27 -> 0.14197015
B14: 5 | C14: 學術部 | F14: 0 | G14: ='表2｜主要表'!H33 -> 0 | H14: ='表2｜主要表'!I33 -> 116558 | I14: ='表2｜主要表'!J33 -> 0.11575581
B15: 6 | C15: 文化部 | F15: ='表3-1｜期入決算附屬表'!G69 -> 103768 | G15: ='表2｜主要表'!H62 -> 0.042535661 | H15: ='表2｜主要表'!I62 -> 213117 | I15: ='表2｜主要表'!J62 -> 0.21165026
B16: 7 | C16: 公關部 | F16: ='表2｜主要表'!G70 -> 0 | G16: ='表2｜主要表'!H70 -> 0 | H16: ='表2｜主要表'!I70 -> 30679 | I16: ='表2｜主要表'!J70 -> 0.030467858
B17: 8 | C17: 選舉罷免執行委員會 | F17: ='表2｜主要表'!G77 -> 50000 | G17: ='表2｜主要表'!H77 -> 0.020495558 | H17: ='表2｜主要表'!I77 -> 219815 | I17: ='表2｜主要表'!J77 -> 0.21830217
B18: 9 | C18: 國際事務部 | F18: ='表2｜主要表'!G85 -> 42918 | G18: ='表2｜主要表'!H85 -> 0.017592567 | H18: ='表2｜主要表'!I85 -> 91524 | I18: ='表2｜主要表'!J85 -> 0.090894104
B19: A | C19: 資訊部 | F19: ='表2｜主要表'!G95 -> 0 | G19: ='表2｜主要表'!H95 -> 0 | H19: ='表2｜主要表'!I95 -> 58690 | I19: ='表2｜主要表'!J95 -> 0.058286077
A21: 2 | B21: 0 | C21: 立法部門 | F21: ='表2｜主要表'!G104 -> 0 | G21: ='表2｜主要表'!H104 -> 0 | H21: ='表2｜主要表'!I104 -> 156075 | I21: ='表2｜主要表'!J104 -> 0.13073743
B22: 1 | C22: 學生代表大會 | F22: ='表2｜主要表'!G105 -> 0 | G22: ='表2｜主要表'!H105 -> 0 | H22: ='表2｜主要表'!I105 -> 156075 | I22: ='表2｜主要表'!J105 -> 1
A24: 3 | B24: 0 | C24: 司法部門 | F24: ='表2｜主要表'!G114 -> 0 | G24: ='表2｜主要表'!H114 -> 0 | H24: ='表2｜主要表'!I114 -> 30800 | I24: ='表2｜主要表'!J114 -> 0.025799858
B25: 1 | C25: 學生法院 | F25: ='表2｜主要表'!G115 -> 0 | G25: ='表2｜主要表'!H115 -> 0 | H25: ='表2｜主要表'!I115 -> 30800 | I25: ='表2｜主要表'!J115 -> 1
A27: 款 | C27: 部門預算
A28: 項 | C28: 單位預算
A29: 目 | C29: 附屬單位預算
A30: 節 | C30: 計畫名稱

Sheet 表2｜主要表
A1: 國立臺灣大學學生會決算案
A2: 主要表
A3: 第38屆第一期間（114-1）
A4: 2025年9月22日至2026年3月15日
A5: 單位計畫別 | E5: 預算科目 | G5: 本期期入 | I5: 本期期出 | K5: 各計畫會費支出情形
A6: 款 | B6: 項 | C6: 目 | D6: 節 | E6: 代碼 | F6: 名稱 | G6: 決算數 | I6: 決算數
F7: 合計 | G7: =G9+G104+G114 -> 2439553 | H7: =G7/G7 -> 1 | I7: ='表3-2｜期出決算附屬表'!G7 -> 1193805 | J7: =I7/I7 -> 1
A9: 1 | B9: 0 | C9: 0 | D9: 0 | F9: 行政部門 | G9: ='表3-1｜期入決算附屬表'!G9 -> 2439553 | H9: =G9/G7 -> 1 | I9: ='表3-2｜期出決算附屬表'!G9 -> 1006930 | J9: ='表3-2｜期出決算附屬表'!H9 -> 0.84346271
B11: 1 | C11: 0 | D11: 0 | F11: 會長 | G11: ='表3-1｜期入決算附屬表'!G11 -> 2133763 | H11: =G11/$G$9 -> 0.87465327 | I11: ='表3-2｜期出決算附屬表'!G12 -> 48600 | J11: ='表3-2｜期出決算附屬表'!H11 -> 0.04826552
C13: 0 | D13: 1 | F13: 一般行政計畫 | G13: ='表3-1｜期入決算附屬表'!G13 -> 2133763 | H13: =G13/G11 -> 1 | I13: ='表3-2｜期出決算附屬表'!G12 -> 48600 | J13: =I13/I11 -> 1 | K13: ="會費支出："&(I13-G13) -> 會費支出：-2085163
C14: 0 | D14: 2 | F14: Line官方帳號計畫 | G14: ='表3-1｜期入決算附屬表'!G19 -> 0 | H14: 0 | I14: ='表3-2｜期出決算附屬表'!G24 -> 0 | J14: 0 | K14: ="會費支出："&(I14-G14) -> 會費支出：0
C15: 9 | D15: 9 | F15: 預備金 | G15: 0 | H15: 0 | I15: 0 | J15: =I15/I11 -> 0 | K15: ="會費支出："&(I15-G15) -> 會費支出：0
B17: 2 | C17: 0 | D17: 0 | F17: 秘書處 | G17: 0 | H17: =G17/$G$9 -> 0 | I17: ='表3-2｜期出決算附屬表'!G33 -> 56943 | J17: ='表3-2｜期出決算附屬表'!H33 -> 0.056551101
C19: 0 | D19: 1 | F19: 一般行政計畫 | G19: 0 | H19: 0 | I19: ='表3-2｜期出決算附屬表'!G34 -> 53228 | J19: =I19/I17 -> 0.93475932 | K19: ="會費支出："&(I19-G19) -> 會費支出：53228
C20: 9 | D20: 9 | F20: 預備金 | G20: 0 | H20: 0 | I20: 0 | J20: =I20/I17 -> 0 | K20: ="會費支出："&(I20-G20) -> 會費支出：0
B22: 3 | C22: 0 | D22: 0 | F22: 財務部 | G22: ='表3-1｜期入決算附屬表'!I27 -> 0 | H22: =G22/$G$9 -> 0 | I22: ='表3-2｜期出決算附屬表'!G52 -> 28050 | J22: ='表3-2｜期出決算附屬表'!H52 -> 0.027856951
C24: 0 | D24: 1 | F24: 一般行政計畫 | G24: ='表3-1｜期入決算附屬表'!I29 -> 0 | H24: 0 | I24: ='表3-2｜期出決算附屬表'!G53 -> 28050 | J24: =I24/I22 -> 1 | K24: ="會費支出："&(I24-G24) -> 會費支出：28050
C25: 9 | D25: 9 | F25: 預備金 | G25: ='表3-1｜期入決算附屬表'!I30 -> 0 | H25: 0 | I25: 0 | J25: =I25/I22 -> 0 | K25: ="會費支出："&(I25-G25) -> 會費支出：0
B27: 4 | C27: 0 | D27: 0 | F27: 學權部 | G27: ='表3-1｜期入決算附屬表'!G32 -> 109104 | H27: =G27/$G$9 -> 0.044722947 | I27: =SUM('表3-2｜期出決算附屬表'!G66) -> 142954 | J27: ='表3-2｜期出決算附屬表'!H66 -> 0.14197015
C29: 0 | D29: 1 | F29: 一般行政計畫 | G29: ='表3-1｜期入決算附屬表'!G34 -> 0 | H29: 0 | I29: ='表3-2｜期出決算附屬表'!G68 -> 22700 | J29: ='表3-2｜期出決算附屬表'!H68 -> 0.15879234 | K29: ="會費支出："&(I29-G29) -> 會費支出：22700
C30: 0 | D30: 2 | F30: 臺灣大學花蓮光復賑災補助計劃 | G30: ='表3-1｜期入決算附屬表'!G35 -> 109104 | H30: 1 | I30: ='表3-2｜期出決算附屬表'!G72 -> 109104 | J30: ='表3-2｜期出決算附屬表'!H72 -> 0.76321054 | K30: ="會費支出："&(I30-G30) -> 會費支出：0
C31: 9 | D31: 9 | F31: 預備金 | G31: ='表3-1｜期入決算附屬表'!G36 -> 0 | H31: 0 | I31: ='表3-2｜期出決算附屬表'!G76 -> 11150 | J31: ='表3-2｜期出決算附屬表'!H76 -> 0.077997118 | K31: ="會費支出："&(I31-G31) -> 會費支出：11150
B33: 5 | C33: 0 | D33: 0 | F33: 學術部 | G33: 0 | H33: =G33/$G$9 -> 0 | I33: ='表3-2｜期出決算附屬表'!G80 -> 116558 | J33: ='表3-2｜期出決算附屬表'!H80 -> 0.11575581
C35: 0 | D35: 1 | F35: 一般行政計畫 | G35: ='表3-1｜期入決算附屬表'!I40 -> 0 | H35: 0 | I35: ='表3-2｜期出決算附屬表'!G82 -> 6000 | J35: =I35/I33 -> 0.051476518 | K35: ="會費支出："&(I35-G35) -> 會費支出：6000
C37: 1 | D37: 0 | F37: 性別平等工作坊 | G37: ='表3-1｜期入決算附屬表'!G42 -> 0 | H37: ='表3-1｜期入決算附屬表'!H42 -> 0 | I37: ='表3-2｜期出決算附屬表'!G85 -> 33400 | J37: ='表3-2｜期出決算附屬表'!H85 -> 0.28655262
D38: 1 | F38: 一般行政計畫 | G38: ='表3-1｜期入決算附屬表'!G43 -> 0 | H38: ='表3-1｜期入決算附屬表'!H43 -> 0 | I38: ='表3-2｜期出決算附屬表'!G86 -> 0 | J38: ='表3-2｜期出決算附屬表'!H86 -> 0 | K38: ="會費支出："&(I38-G38) -> 會費支出：0
D39: 2 | F39: 生理用品交換站暨月經議題倡議計畫 | G39: ='表3-1｜期入決算附屬表'!G44 -> 0 | H39: ='表3-1｜期入決算附屬表'!H44 -> 0 | I39: ='表3-2｜期出決算附屬表'!G89 -> 1600 | J39: ='表3-2｜期出決算附屬表'!H89 -> 0.047904192 | K39: ="會費支出："&(I39-G39) -> 會費支出：1600
D40: 3 | F40: 性別樹洞 | G40: ='表3-1｜期入決算附屬表'!G45 -> 0 | H40: ='表3-1｜期入決算附屬表'!H45 -> 0 | I40: ='表3-2｜期出決算附屬表'!G93 -> 3400 | J40: ='表3-2｜期出決算附屬表'!H93 -> 0.10179641 | K40: ="會費支出："&(I40-G40) -> 會費支出：3400
D41: 4 | F41: 台大校內同志大遊行 | G41: ='表3-1｜期入決算附屬表'!G46 -> 0 | H41: ='表3-1｜期入決算附屬表'!H46 -> 0 | I41: ='表3-2｜期出決算附屬表'!G97 -> 10300 | J41: ='表3-2｜期出決算附屬表'!H97 -> 0.30838323 | K41: ="會費支出："&(I41-G41) -> 會費支出：10300
D42: 5 | F42: 專欄文章藉親密關係面向及女性主義視角 | G42: ='表3-1｜期入決算附屬表'!G47 -> 0 | H42: ='表3-1｜期入決算附屬表'!H47 -> 0 | I42: ='表3-2｜期出決算附屬表'!G108 -> 10000 | J42: ='表3-2｜期出決算附屬表'!H108 -> 0.2994012 | K42: ="會費支出："&(I42-G42) -> 會費支出：10000
D43: 6 | F43: 愛在校園蔓延時_性工坊午餐live podcast活動 | G43: ='表3-1｜期入決算附屬表'!G48 -> 0 | H43: ='表3-1｜期入決算附屬表'!H48 -> 0 | I43: ='表3-2｜期出決算附屬表'!G112 -> 8100 | J43: ='表3-2｜期出決算附屬表'!H112 -> 0.24251497 | K43: ="會費支出："&(I43-G43) -> 會費支出：8100
C45: 2 | D45: 0 | F45: 轉型正義組 | G45: ='表3-1｜期入決算附屬表'!G50 -> 0 | H45: ='表3-1｜期入決算附屬表'!H50 -> 0 | I45: ='表3-2｜期出決算附屬表'!G120 -> 13312 | J45: ='表3-2｜期出決算附屬表'!H120 -> 0.11420923
D46: 1 | F46: 一般行政計畫 | G46: ='表3-1｜期入決算附屬表'!G51 -> 0 | H46: ='表3-1｜期入決算附屬表'!H51 -> 0 | I46: ='表3-2｜期出決算附屬表'!G121 -> 0 | J46: ='表3-2｜期出決算附屬表'!H121 -> 0 | K46: ="會費支出："&(I46-G46) -> 會費支出：0
D47: 2 | F47: 社群經營【轉型正義小組社群經營】 | G47: ='表3-1｜期入決算附屬表'!G52 -> 0 | H47: ='表3-1｜期入決算附屬表'!H52 -> 0 | I47: ='表3-2｜期出決算附屬表'!G123 -> 3152 | J47: ='表3-2｜期出決算附屬表'!H123 -> 0.23677885 | K47: ="會費支出："&(I47-G47) -> 會費支出：3152
D48: 3 | F48: 走讀活動【白恐電影賞析：人權奮鬥的記憶傳承】 | G48: ='表3-1｜期入決算附屬表'!G53 -> 0 | H48: ='表3-1｜期入決算附屬表'!H53 -> 0 | I48: ='表3-2｜期出決算附屬表'!G129 -> 10160 | J48: ='表3-2｜期出決算附屬表'!H129 -> 0.76322115 | K48: ="會費支出："&(I48-G48) -> 會費支出：10160
G49: ='表3-1｜期入決算附屬表'!G54 -> 0 | H49: ='表3-1｜期入決算附屬表'!H54 -> 0
C50: 3 | D50: 0 | F50: 永續執行組 | G50: ='表3-1｜期入決算附屬表'!G55 -> 0 | H50: ='表3-1｜期入決算附屬表'!H55 -> 0 | I50: ='表3-2｜期出決算附屬表'!G139 -> 22400 | J50: ='表3-2｜期出決算附屬表'!H139 -> 0.192179
D51: 1 | F51: 一般行政計畫 | G51: ='表3-1｜期入決算附屬表'!G56 -> 0 | H51: ='表3-1｜期入決算附屬表'!H56 -> 0 | I51: ='表3-2｜期出決算附屬表'!G140 -> 2000 | J51: ='表3-2｜期出決算附屬表'!H140 -> 0.089285714 | K51: ="會費支出："&(I51-G51) -> 會費支出：2000
D52: 2 | F52: 從剩食減量到永續發展：校園綠色行動計畫 | G52: ='表3-1｜期入決算附屬表'!G57 -> 0 | H52: ='表3-1｜期入決算附屬表'!H57 -> 0 | I52: ='表3-2｜期出決算附屬表'!G142 -> 20400 | J52: ='表3-2｜期出決算附屬表'!H142 -> 0.91071429 | K52: ="會費支出："&(I52-G52) -> 會費支出：20400
C54: 4 | D54: 0 | F54: 本土語言小組 | G54: ='表3-1｜期入決算附屬表'!G60 -> 0 | H54: ='表3-1｜期入決算附屬表'!H60 -> 0 | I54: ='表3-2｜期出決算附屬表'!G151 -> 33100 | J54: ='表3-2｜期出決算附屬表'!H151 -> 0.28397879
...

Sheet 表3-1｜期入決算附屬表
A1: 國立臺灣大學學生會決算案
A2: 期入決算副屬表
A3: 第38屆第一期間（114-1）
A4: 2025年9月22日至2026年3月15日
A5: 單位計畫別 | E5: 預算科目 | G5: 本期間 | H5: 本期間 | I5: 本期間 | J5: 本期間 | K5: 本期間 | L5: 本期間 | M5: 說明 | N5: 委員會意見｜大會審議結果
A6: 款 | B6: 項 | C6: 目 | D6: 節 | E6: 代碼 | F6: 名稱 | G6: 決算數 | H6: 決算百分比 | I6: 預算數 | J6: 百分比 | K6: 餘絀數 | L6: 預算執行率
F7: 合計 | G7: =G9 -> 2439553 | H7: 1 | I7: =I9+I128+I140 -> 2589130 | J7: 1 | K7: =I7-G7 -> 149577 | L7: =G7/I7 -> 0.94222886
A9: 1 | B9: 0 | C9: 0 | D9: 0 | F9: 行政部門 | G9: =SUM(G11,G22,G27,G32,G38,G69,G81,G88,G99,G119,) -> 2439553 | H9: 1 | I9: =I11+I22+I27+I32+I38+I69+I81+I88+I99+I119 -> 2589130 | J9: =I9/$I$7 -> 1 | K9: =K11+K69+K99 -> -38681 | L9: =G9/I9 -> 0.94222886
B11: 1 | C11: 0 | D11: 0 | F11: 會長 | G11: =SUM(G13,G19,G20) -> 2133763 | H11: =G11/G9 -> 0.87465327 | I11: =SUM(I13,I19,I20) -> 2095497 | J11: =I11/$I$9 -> 0.80934407 | K11: =SUM(K13,K19,K20) -> 38266 | L11: =G11/I11 -> 1.0182611
C13: 0 | D13: 1 | F13: 一般行政計畫 | G13: =SUM(G14:G18) -> 2133763 | H13: =G13/$G$11 -> 1 | I13: =I14+I17 -> 2095497 | J13: =I13/$I$11 -> 1 | K13: =G13-I13 -> 38266 | L13: =G13/I13 -> 1.0182611
E14: Z01 | F14: 會費收入 | G14: 0 | H14: =G14/G13 -> 0 | I14: 1217715 | J14: =I14/$I$11 -> 0.58111035 | K14: =G14-I14 -> -1217715 | L14: =G14/I14 -> 0
E15: Z04 | F15: 公關贊助收入 | G15: 0 | H15: =G15/G13 -> 0 | I15: 0 | J15: =I15/$I$13 -> 0 | K15: =G15-I15 -> 0 | L15: 0 | M15: 各類廠商贊助。
E16: Z52 | F16: 學校專案補助 | G16: 38266 | H16: =G16/G13 -> 0.017933576 | I16: 0 | J16: =I16/$I$13 -> 0 | K16: =G16-I16 -> 38266 | L16: 1
E17: Z99 | F17: 前期轉入 | G17: 2095497 | H17: =G17/G13 -> 0.98206642 | I17: 877782 | J17: =I17/$I$13 -> 0.41888965 | K17: =G17-I17 -> 1217715 | L17: =G17/I17 -> 2.3872636 | M17: 中信餘額：1,602,217
M18: 郵局餘額：493,280
C19: 0 | D19: 2 | F19: Line官方帳號計畫 | G19: 0 | H19: 0 | I19: 0 | J19: 0 | K19: =G19-I19 -> 0 | L19: 0
C20: 9 | D20: 9 | F20: 預備金 | G20: 0 | H20: 0 | I20: 0 | J20: =I20/$I$11 -> 0 | K20: =G20-I20 -> 0 | L20: 0
B22: 2 | C22: 0 | D22: 0 | F22: 秘書處 | G22: 0 | H22: 0 | I22: 0 | J22: =I22/$I$9 -> 0 | K22: 0 | L22: 0
C24: 0 | D24: 1 | F24: 一般行政計畫 | G24: 0 | H24: 0 | I24: 0 | J24: 0 | K24: =G24-I24 -> 0 | L24: 0
C25: 9 | D25: 9 | F25: 預備金 | G25: 0 | H25: 0 | I25: 0 | J25: 0 | K25: =G25-I25 -> 0 | L25: 0
B27: 3 | C27: 0 | D27: 0 | F27: 財務部 | G27: 0 | H27: 0 | I27: 0 | J27: =I27/$I$9 -> 0 | K27: 0 | L27: 0
C29: 0 | D29: 1 | F29: 一般行政計畫 | G29: 0 | H29: 0 | I29: 0 | J29: 0 | K29: =G29-I29 -> 0 | L29: 0
C30: 9 | D30: 9 | F30: 預備金 | G30: 0 | H30: 0 | I30: 0 | J30: 0 | K30: =G30-I30 -> 0 | L30: 0
B32: 4 | C32: 0 | D32: 0 | F32: 學權部 | G32: =SUM(G34,G35,G36) -> 109104 | H32: 0 | I32: =SUM(I35) -> 220000 | J32: =I32/$I$9 -> 0.084970627 | K32: =SUM(K34:K36) -> -110896 | L32: 0
C34: 0 | D34: 1 | F34: 一般行政計畫 | G34: 0 | H34: 0 | I34: 0 | J34: 0 | K34: =G34-I34 -> 0 | L34: 0
C35: 0 | D35: 2 | F35: 臺灣大學花蓮光復賑災補助計劃 | G35: 109104 | H35: =G35/$G$32 -> 1 | I35: 220000 | J35: =I35/I32 -> 1 | K35: =G35-I35 -> -110896 | L35: =G35/I35 -> 0.49592727
C36: 9 | D36: 9 | F36: 預備金 | G36: 0 | H36: 0 | I36: 0 | J36: 0 | K36: =G36-I36 -> 0 | L36: 0
B38: 5 | C38: 0 | D38: 0 | F38: 學術部 | G38: 0 | H38: 0 | I38: 0 | J38: =I38/$I$9 -> 0 | K38: 0 | L38: 0
C40: 0 | D40: 1 | F40: 一般行政計畫 | G40: 0 | H40: 0 | I40: 0 | J40: 0 | K40: =G40-I40 -> 0 | L40: 0
C42: 1 | D42: 0 | F42: 性別平等工作坊 | G42: 0 | H42: 0 | I42: 0 | J42: 0 | K42: =G42-I42 -> 0 | L42: 0
D43: 1 | F43: 一般行政計畫 | G43: 0 | H43: 0 | I43: 0 | J43: 0 | K43: =G43-I43 -> 0 | L43: 0
D44: 2 | F44: 生理用品交換站暨月經議題倡議計畫 | G44: 0 | H44: 0 | I44: 0 | J44: 0 | K44: =G44-I44 -> 0 | L44: 0
D45: 3 | F45: 性別樹洞 | G45: 0 | H45: 0 | I45: 0 | J45: 0 | K45: =G45-I45 -> 0 | L45: 0
D46: 4 | F46: 台大校內同志大遊行 | G46: 0 | H46: 0 | I46: 0 | J46: 0 | K46: =G46-I46 -> 0 | L46: 0
D47: 5 | F47: 專欄文章藉親密關係面向及女性主義視角 | G47: 0 | H47: 0 | I47: 0 | J47: 0 | K47: =G47-I47 -> 0 | L47: 0
D48: 6 | F48: 愛在校園蔓延時_性工坊午餐live podcast活動 | G48: 0 | H48: 0 | I48: 0 | J48: 0 | K48: =G48-I48 -> 0 | L48: 0
C50: 2 | D50: 0 | F50: 轉型正義組 | G50: 0 | H50: 0 | I50: 0 | J50: 0 | K50: =G50-I50 -> 0 | L50: 0
D51: 1 | F51: 一般行政計畫 | G51: 0 | H51: 0 | I51: 0 | J51: 0 | K51: =G51-I51 -> 0 | L51: 0
D52: 2 | F52: 社群經營【轉型正義小組社群經營】 | G52: 0 | H52: 0 | I52: 0 | J52: 0 | K52: =G52-I52 -> 0 | L52: 0
D53: 3 | F53: 走讀活動【白恐電影賞析：人權奮鬥的記憶傳承】 | G53: 0 | H53: 0 | I53: 0 | J53: 0 | K53: 0 | L53: 0
...

Sheet 表3-2｜期出決算附屬表
A1: 國立臺灣大學學生會決算案
A2: 期出決算副屬表
A3: 第38屆第一期間（114-1）
A4: 2025年9月22日至2026年3月15日
A5: 單位計畫別 | E5: 預算科目 | G5: 本期間 | H5: 本期間 | I5: 本期間 | J5: 本期間 | K5: 本期間 | L5: 本期間 | M5: 說明 | N5: 委員會意見｜大會審議結果 | O5: 各部門備註
A6: 款 | B6: 項 | C6: 目 | D6: 節 | E6: 代碼 | F6: 名稱 | G6: 決算數 | H6: 決算百分比 | I6: 預算數 | J6: 百分比 | K6: 餘絀數 | L6: 預算執行率
F7: 合計 | G7: =G9+G365+G427 -> 1193805 | H7: 1 | I7: =I9+I365+I427 -> 1877453.4 | J7: 1 | K7: =I7-G7 -> 683648.37 | L7: =G7/I7 -> 0.635864
A9: 1 | B9: 0 | C9: 0 | D9: 0 | F9: 行政部門 | G9: =SUM(G11,G33,G52,G66,G80,G179,G220,G239,G287,G341) -> 1006930 | H9: =G9/G7 -> 0.84346271 | I9: =I11+I33+I52+I66+I80+I179+I220+I239+I287+I341 -> 1539832.5 | J9: =I9/$I$7 -> 0.82017082 | K9: =K11+K33+K52+K66+K80+K179+K220+K239+K287+K341 -> 417837.47 | L9: =G9/I9 -> 0.65392179
B11: 1 | C11: 0 | D11: 0 | F11: 會長 | G11: =SUM(G12,G24,G29) -> 48600 | H11: =G11/$G$9 -> 0.04826552 | I11: =I12+I24+I29 -> 147684.21 | J11: =I11/$I$9 -> 0.095909271 | K11: =SUM(K12,K24,K29) -> 99084.211 | L11: =G11/I11 -> 0.32908054
C12: 0 | D12: 1 | F12: 一般行政計畫 | G12: =SUM(G13:G23) -> 48600 | H12: =G12/G11 -> 1 | I12: =SUM(I13:I23) -> 125700 | J12: =I12/$I$11 -> 0.85114041 | K12: =SUM(K13:K23) -> 77100 | L12: =G12/I12 -> 0.38663484
E13: A02 | F13: 工作費 | G13: 33600 | H13: =G13/$G$12 -> 0.69135802 | I13: 69000 | J13: =I13/$I$12 -> 0.54892601 | K13: =I13-G13 -> 35400 | L13: =G13/I13 -> 0.48695652 | M13: 會長工作費：每小時 200 元，以每週 3小時計，共 23 週。共計200*3*23=13,800元。本工作費會長個人領取後，計劃支用於學生會事務上，若全學年結束後仍有剩餘，將回捐回學生會或校務基金運營使用。 | O13: 依實際執行狀況核銷。
M14: 副會長工作費：每小時 200 元，以每週 3小時計，共 23 週，共 2 名。共計200*3*23*2=27,600元。
M15: 會長秘書工作費：每小時 200 元，以每週 3 小時計，共 23 週，共 2 名。共計200*3*23*2=27,600元。
E16: B01 | F16: 行政費 | G16: 8000 | H16: =G16/$G$12 -> 0.16460905 | I16: 18000 | J16: =I16/$I$12 -> 0.14319809 | K16: =I16-G16 -> 10000 | L16: =G16/I16 -> 0.44444444 | M16: 依作業要點編列，會長、兩位副會長行政費，本期間以6個月計算，1,000元 / 月。共計1,000*6*3=18,000元 | N16: 凍結9,000元，解凍條件：將凍結部分之動支計畫送大會審議並同意後始得動支。 | O16: 依實際執行狀況核銷。
E17: B02 | F17: 餐費 | G17: 0 | H17: =G17/$G$12 -> 0 | I17: 7200 | J17: =I17/$I$12 -> 0.057279236 | K17: =I17-G17 -> 7200 | L17: =G17/I17 -> 0 | M17: 為促進會內連結，加深日後之協作與交流，特舉辦全會交流工作坊， | O17: 實際未辦理。
M18: 全會交流工作坊參與人員之正餐餐點費用，每次預計30人，共兩次。共計30*120*2=7,200元
E19: B05 | F19: 印刷費 | G19: 0 | H19: =G19/$G$12 -> 0 | I19: 1000 | J19: =I19/$I$12 -> 0.0079554495 | K19: =I19-G19 -> 1000 | L19: =G19/I19 -> 0 | M19: 臨時需印製各類文件、海報之費用。 | O19: 依實際執行狀況核銷。
E20: B20 | F20: 委辦費 | G20: 7000 | H20: =G20/$G$12 -> 0.14403292 | I20: 15000 | J20: =I20/$I$12 -> 0.11933174 | K20: =I20-G20 -> 8000 | L20: =G20/I20 -> 0.46666667 | M20: 承接 37-3 活大 237 會辦垃圾清運效益有所成果，本會期預計進一步請打掃公司清掃活大 237 空間將此空間之討論功能效益進一步擴展，同時為對應解決牆壁粉刷剝落之情形進行相關牆壁粉刷之維護任務。此外，也針對大一女地下室之學生會空間，一併進行垃圾清運與空間清掃之任務。 | O20: 依實際執行狀況核銷。
E21: B99 | F21: 雜支 | G21: 0 | H21: =G21/$G$12 -> 0 | I21: 500 | J21: =I21/$I$12 -> 0.0039777247 | K21: =I21-G21 -> 500 | L21: =G21/I21 -> 0 | M21: 依作業要點編列，每一計畫不超過500元。 | O21: 依實際執行狀況核銷。
E22: C01 | F22: 設備費 | G22: 0 | H22: =G22/$G$12 -> 0 | I22: 15000 | J22: =I22/$I$12 -> 0.11933174 | K22: =I22-G22 -> 15000 | L22: =G22/I22 -> 0 | M22: (1) 擬添購會辦投影機，共10,000元。 | O22: 實際未辦理。
M23: (2) 擬添購會辦水冷氣，共5,000元。
C24: 0 | D24: 2 | F24: Line官方帳號計畫 | G24: =SUM(G25:G27) -> 0 | H24: =G24/G11 -> 0 | I24: =SUM(I25:I27) -> 14600 | J24: =I24/I11 -> 0.098859587 | K24: =SUM(K25:K27) -> 14600 | L24: =G24/I24 -> 0
E25: A02 | F25: 工作費 | G25: 0 | H25: 0 | I25: 9600 | J25: =I25/$I$24 -> 0.65753425 | K25: =I25-G25 -> 9600 | L25: =G25/I25 -> 0 | M25: 帳號經營費用：每小時工資200元，每月工時8小時，共6個月。共計200*8*6=9,600元。
E26: B08 | F26: 廣告費 | G26: 0 | H26: 0 | I26: 1000 | J26: =I26/$I$24 -> 0.068493151 | K26: =I26-G26 -> 1000 | L26: =G26/I26 -> 0 | M26: 線下宣傳：海報與立板印製，共4張，估計1,000元。
E27: B12 | F27: 資通服務使用費 | G27: 0 | H27: 0 | I27: 4000 | J27: =I27/$I$24 -> 0.2739726 | K27: =I27-G27 -> 4000 | L27: =G27/I27 -> 0 | M27: Line官方帳號月費：使用中用量服務，估計4,800元 | N27: 一、減列800元。 二、修正科目名稱為「資通服務使用費」 （已修改數額及文字如左）
C29: 9 | D29: 9 | F29: 預備金 | G29: 0 | H29: =G29/G11 -> 0 | I29: =(I12+I24)/95*5 -> 7384.2105 | J29: =I29/I11 -> 0.05 | K29: =I29-G29 -> 7384.2105 | L29: =G29/I29 -> 0 | M29: 依預算法編列單位預算 5%。
B33: 2 | C33: 0 | D33: 0 | F33: 秘書處 | G33: =G34+G48 -> 56943 | H33: =G33/$G$9 -> 0.056551101 | I33: =I34+I48 -> 84105.263 | J33: =I33/$I$9 -> 0.054619749 | K33: =K34+K48 -> 27162.263 | L33: =G33/I33 -> 0.67704443
C34: 0 | D34: 1 | F34: 一般行政計畫 | G34: =SUM(G35:G47) -> 53228 | H34: =G34/G33 -> 0.93475932 | I34: =SUM(I35:I47) -> 79900 | J34: =I34/$I$33 -> 0.95 | K34: =SUM(K35:K47) -> 26672 | L34: =G34/I34 -> 0.66618273
E35: A02 | F35: 工作費 | G35: 19900 | H35: =G35/$G$34 -> 0.37386338 | I35: 20000 | J35: =I35/$I$34 -> 0.25031289 | K35: =I35-G35 -> 100 | L35: =G35/I35 -> 0.995 | M35: (1) 活動場地組：預計60小時
M36: (2) 空間財產組：預計30小時
M37: (3) 文書檔案組：預計10小時
M38: 每小時200元，共100小時，共計200*100=20,000元。
E39: B01 | F39: 行政費 | G39: 3000 | H39: =G39/$G$34 -> 0.056361314 | I39: 3000 | J39: =I39/$I$34 -> 0.037546934 | K39: =I39-G39 -> 0 | L39: =G39/I39 -> 1 | M39: 依作業要點編列，本期間以6個月計算，500元 / 月。共計500*6=3,000元
E40: B04 | F40: 耗材費 | G40: 2902 | H40: =G40/$G$34 -> 0.054520177 | I40: 3000 | J40: =I40/$I$34 -> 0.037546934 | K40: =I40-G40 -> 98 | L40: =G40/I40 -> 0.96733333 | M40: 預計作為全會耗材購置使用
E41: B05 | F41: 印刷費 | G41: 279 | H41: =G41/$G$34 -> 0.0052416022 | I41: 300 | J41: =I41/$I$34 -> 0.0037546934 | K41: =I41-G41 -> 21 | L41: =G41/I41 -> 0.93 | M41: 作為場地活動申請文件之印刷費
E42: B06 | F42: 場地費 | G42: 17040 | H42: =G42/$G$34 -> 0.32013226 | I42: 30000 | J42: =I42/$I$34 -> 0.37546934 | K42: =I42-G42 -> 12960 | L42: =G42/I42 -> 0.568 | M42: 各部門例會之場地費，本會期擬開例會之部門為資訊部、國際部、學術部轉型正義小組、學術部性別平等工作坊、學術部本土語言小組、文化部台大電影節
E43: B14 | F43: 手續費 | G43: 100 | H43: =G43/$G$34 -> 0.0018787105 | I43: 100 | J43: =I43/$I$34 -> 0.0012515645 | K43: =I43-G43 -> 0 | L43: =G43/I43 -> 1 | M43: 匯款給承包廠商之手續費用
E44: B15 | F44: 設備租借費 | G44: 0 | H44: =G44/$G$34 -> 0 | I44: 8000 | J44: =I44/$I$34 -> 0.10012516 | K44: =I44-G44 -> 8000 | L44: =G44/I44 -> 0 | M44: 租用設備臨時使用之費用 | O44: 實際未有需求故無辦理
E45: B99 | F45: 雜支 | G45: 0 | H45: =G45/$G$34 -> 0 | I45: 500 | J45: =I45/$I$34 -> 0.0062578223 | K45: =I45-G45 -> 500 | L45: =G45/I45 -> 0 | M45: 依作業要點編列，每一計畫不超過 500 元。 | O45: 實際未有需求故無辦理
E46: C01 | F46: 設備費 | G46: 5007 | H46: =G46/$G$34 -> 0.094067032 | I46: 10000 | J46: =I46/$I$34 -> 0.12515645 | K46: =I46-G46 -> 4993 | L46: =G46/I46 -> 0.5007 | M46: 設備維修添購，老舊物品汰換
...

Sheet 可以砍的地方
A1: 1201 | B1: A02 | C1: 16800 | E1: 返鄉專車 | F1: 20-30萬
A2: 1301 | B2: B03 | C2: 3040 | E2: 校慶 | F2: 45000 | G2: 跟院學生會合辦
B3: B10 | C3: 300 | G3: 攤位 帳篷
A4: 1402 | C4: 6500
A5: 1432 | C5: 6800
A6: 1613 | C6: 15000
A7: 1633 | C7: 15000
C12: =SUM(C1:C11) -> 63440
